<?xml version="1.0" ?>

<sdf version="1.6">
  <world name="testwrld">
    <physics name="1ms" type="ignored">
      <max_step_size>0.001</max_step_size>
      <real_time_factor>1.0</real_time_factor>
    </physics>
    <plugin
      filename="libignition-gazebo-physics-system.so"
      name="ignition::gazebo::systems::Physics">
    </plugin>
    <plugin
      filename="libignition-gazebo-sensors-system.so"
      name="ignition::gazebo::systems::Sensors">
      <render_engine>ogre2</render_engine>
    </plugin>
    <plugin
      filename="libignition-gazebo-scene-broadcaster-system.so"
      name="ignition::gazebo::systems::SceneBroadcaster">
    </plugin>

    <gui fullscreen="0">

      <!-- 3D scene -->
      <plugin filename="MinimalScene" name="3D View">
        <ignition-gui>
          <title>3D View</title>
          <property type="bool" key="showTitleBar">false</property>
          <property type="string" key="state">docked</property>
        </ignition-gui>

        <engine>ogre2</engine>
        <scene>scene</scene>
        <ambient_light>0.4 0.4 0.4</ambient_light>
        <background_color>0.8 0.8 0.8</background_color>
        <camera_pose>-6 0 6 0 0.5 0</camera_pose>
      </plugin>

      <!-- Plugins that add functionality to the scene -->
      <plugin filename="EntityContextMenuPlugin" name="Entity context menu">
        <ignition-gui>
          <property key="state" type="string">floating</property>
          <property key="width" type="double">5</property>
          <property key="height" type="double">5</property>
          <property key="showTitleBar" type="bool">false</property>
        </ignition-gui>
      </plugin>
      <plugin filename="GzSceneManager" name="Scene Manager">
        <ignition-gui>
          <property key="resizable" type="bool">false</property>
          <property key="width" type="double">5</property>
          <property key="height" type="double">5</property>
          <property key="state" type="string">floating</property>
          <property key="showTitleBar" type="bool">false</property>
        </ignition-gui>
      </plugin>
      <plugin filename="InteractiveViewControl" name="Interactive view control">
        <ignition-gui>
          <property key="resizable" type="bool">false</property>
          <property key="width" type="double">5</property>
          <property key="height" type="double">5</property>
          <property key="state" type="string">floating</property>
          <property key="showTitleBar" type="bool">false</property>
        </ignition-gui>
      </plugin>
      <plugin filename="CameraTracking" name="Camera Tracking">
        <ignition-gui>
          <property key="resizable" type="bool">false</property>
          <property key="width" type="double">5</property>
          <property key="height" type="double">5</property>
          <property key="state" type="string">floating</property>
          <property key="showTitleBar" type="bool">false</property>
        </ignition-gui>
      </plugin>
      <!-- World control -->
      <plugin filename="WorldControl" name="World control">
        <ignition-gui>
          <title>World control</title>
          <property type="bool" key="showTitleBar">false</property>
          <property type="bool" key="resizable">false</property>
          <property type="double" key="height">72</property>
          <property type="double" key="width">121</property>
          <property type="double" key="z">1</property>

          <property type="string" key="state">floating</property>
          <anchors target="3D View">
            <line own="left" target="left"/>
            <line own="bottom" target="bottom"/>
          </anchors>
        </ignition-gui>

        <play_pause>true</play_pause>
        <step>true</step>
        <start_paused>true</start_paused>
        <use_event>true</use_event>

      </plugin>

      <!-- World statistics -->
      <plugin filename="WorldStats" name="World stats">
        <ignition-gui>
          <title>World stats</title>
          <property type="bool" key="showTitleBar">false</property>
          <property type="bool" key="resizable">false</property>
          <property type="double" key="height">110</property>
          <property type="double" key="width">290</property>
          <property type="double" key="z">1</property>

          <property type="string" key="state">floating</property>
          <anchors target="3D View">
            <line own="right" target="right"/>
            <line own="bottom" target="bottom"/>
          </anchors>
        </ignition-gui>

        <sim_time>true</sim_time>
        <real_time>true</real_time>
        <real_time_factor>true</real_time_factor>
        <iterations>true</iterations>
      </plugin>


      <!-- Inspector -->
      <plugin filename="ComponentInspector" name="Component inspector">
        <ignition-gui>
          <property type="string" key="state">docked</property>
        </ignition-gui>
      </plugin>

      <!-- Entity tree -->
      <plugin filename="EntityTree" name="Entity tree">
        <ignition-gui>
          <property type="string" key="state">docked</property>
        </ignition-gui>
      </plugin>
    </gui>

    <light type="directional" name="sun">
      <cast_shadows>true</cast_shadows>
      <pose>0 0 10 0 0 0</pose>
      <diffuse>0.8 0.8 0.8 1</diffuse>
      <specular>0.2 0.2 0.2 1</specular>
      <attenuation>
        <range>1000</range>
        <constant>0.9</constant>
        <linear>0.01</linear>
        <quadratic>0.001</quadratic>
      </attenuation>
      <direction>-0.5 0.1 -0.9</direction>
    </light>

    <model name="ground_plane">
      <static>true</static>
      <link name="link">
        <collision name="collision">
          <geometry>
            <box>
              <size>30 30 0.1</size>
            </box>
          </geometry>
        </collision>
        <visual name="visual">
          <geometry>
            <box>
              <size>30 30 0.1</size>
            </box>
          </geometry>
          <material>
            <ambient>0.8 0.8 0.8 1</ambient>
            <diffuse>0.8 0.8 0.8 1</diffuse>
            <specular>0.8 0.8 0.8 1</specular>
          </material>
        </visual>
      </link>
    </model>




    <model name="box">
      <static>true</static>
      <pose>10 10 -0.44 0 0 0</pose>
      <link name="box_link">
        <inertial>
          <inertia>
            <ixx>1</ixx>
            <ixy>0</ixy>
            <ixz>0</ixz>
            <iyy>1</iyy>
            <iyz>0</iyz>
            <izz>1</izz>
          </inertia>
          <mass>1.0</mass>
        </inertial>
        <collision name="box_collision">
          <geometry>
            <box>
              <size>1 1 1</size>
            </box>
          </geometry>
        </collision>

        <visual name="box_visual">
          <geometry>
            <box>
              <size>1 1 1</size>
            </box>
          </geometry>
          <material>
            <ambient>1 0 0 1</ambient>
            <diffuse>1 0 0 1</diffuse>
            <specular>1 0 0 1</specular>
          </material>
        </visual>
      </link>
    </model>



    <model name='vehicle_blue1'>
      <pose>0 0 0.325 0 0 0.0</pose>
      <link name='chassis'>
        <pose>0 0 0.175 0 -0 0</pose>
        <inertial>
          <mass>0.3</mass>
          <inertia>
            <ixx>0.1</ixx>
            <ixy>0</ixy>
            <ixz>0</ixz>
            <iyy>0.1</iyy>
            <iyz>0</iyz>
            <izz>0.1</izz>
          </inertia>
        </inertial>
        <visual name='visual'>
          <geometry>
            <box>
              <size>1 1 0.568726</size>
            </box>
          </geometry>
          <material>
            <ambient>0.5 0.5 1.0 1</ambient>
            <diffuse>0.5 0.5 1.0 1</diffuse>
            <specular>0.0 0.0 1.0 1</specular>
          </material>
        </visual>
        <collision name='collision'>
          <geometry>
            <box>
              <size>1 1 0.568726</size>
            </box>
          </geometry>
        </collision>
      </link>

      <link name='left_wheel'>
        <pose>0 0.625029 -0.025 -1.5707 0 0</pose>
        <inertial>
          <mass>0.2</mass>
          <inertia>
            <ixx>0.145833</ixx>
            <ixy>0</ixy>
            <ixz>0</ixz>
            <iyy>0.145833</iyy>
            <iyz>0</iyz>
            <izz>0.125</izz>
          </inertia>
        </inertial>
        <visual name='visual'>
          <geometry>
            <sphere>
              <radius>0.3</radius>
            </sphere>
          </geometry>
          <material>
            <ambient>0.2 0.2 0.2 1</ambient>
            <diffuse>0.2 0.2 0.2 1</diffuse>
            <specular>0.2 0.2 0.2 1</specular>
          </material>
        </visual>
        <collision name='collision'>
          <geometry>
            <sphere>
              <radius>0.3</radius>
            </sphere>
          </geometry>
        </collision>
      </link>

      <link name='right_wheel'>
        <pose>0 -0.625029 -0.025 -1.5707 0 0</pose>
        <inertial>
          <mass>0.2</mass>
          <inertia>
            <ixx>0.145833</ixx>
            <ixy>0</ixy>
            <ixz>0</ixz>
            <iyy>0.145833</iyy>
            <iyz>0</iyz>
            <izz>0.125</izz>
          </inertia>
        </inertial>
        <visual name='visual'>
          <geometry>
            <sphere>
              <radius>0.3</radius>
            </sphere>
          </geometry>
          <material>
            <ambient>0.2 0.2 0.2 1</ambient>
            <diffuse>0.2 0.2 0.2 1</diffuse>
            <specular>0.2 0.2 0.2 1</specular>
          </material>
        </visual>
        <collision name='collision'>
          <geometry>
            <sphere>
              <radius>0.3</radius>
            </sphere>
          </geometry>
        </collision>
      </link>

      <link name='caster'>
        <pose>-0.5 -0 -0.125 0 -0 0</pose>
        <inertial>
          <mass>0.1</mass>
          <inertia>
            <ixx>0.1</ixx>
            <ixy>0</ixy>
            <ixz>0</ixz>
            <iyy>0.1</iyy>
            <iyz>0</iyz>
            <izz>0.1</izz>
          </inertia>
        </inertial>
        <visual name='visual'>
          <geometry>
            <sphere>
              <radius>0.2</radius>
            </sphere>
          </geometry>
          <material>
            <ambient>0.2 0.2 0.2 1</ambient>
            <diffuse>0.2 0.2 0.2 1</diffuse>
            <specular>0.2 0.2 0.2 1</specular>
          </material>
        </visual>
        <collision name='collision'>
          <geometry>
            <sphere>
              <radius>0.2</radius>
            </sphere>
          </geometry>
        </collision>
      </link>
      
      
      <link name='caster2'>
        <pose>0.5 -0 -0.125 0 -0 0</pose>
        <inertial>
          <mass>0.1</mass>
          <inertia>
            <ixx>0.1</ixx>
            <ixy>0</ixy>
            <ixz>0</ixz>
            <iyy>0.1</iyy>
            <iyz>0</iyz>
            <izz>0.1</izz>
          </inertia>
        </inertial>
        <visual name='visual'>
          <geometry>
            <sphere>
              <radius>0.2</radius>
            </sphere>
          </geometry>
          <material>
            <ambient>0.2 0.2 0.2 1</ambient>
            <diffuse>0.2 0.2 0.2 1</diffuse>
            <specular>0.2 0.2 0.2 1</specular>
          </material>
        </visual>
        <collision name='collision'>
          <geometry>
            <sphere>
              <radius>0.2</radius>
            </sphere>
          </geometry>
        </collision>
      </link>

      <joint name='left_wheel_joint' type='revolute'>
        <parent>chassis</parent>
        <child>left_wheel</child>
        <axis>
          <xyz>0 0 1</xyz>
          <limit>
            <lower>-1.79769e+308</lower>
            <upper>1.79769e+308</upper>
          </limit>
        </axis>
      </joint>

      <joint name='right_wheel_joint' type='revolute'>
        <parent>chassis</parent>
        <child>right_wheel</child>
        <axis>
          <xyz>0 0 1</xyz>
          <limit>
            <lower>-1.79769e+308</lower>
            <upper>1.79769e+308</upper>
          </limit>
        </axis>
      </joint>

      <joint name='caster_wheel' type='ball'>
        <parent>chassis</parent>
        <child>caster</child>
      </joint>
      
      <joint name='caster_wheel2' type='ball'>
        <parent>chassis</parent>
        <child>caster2</child>
      </joint>

      <plugin
        filename="libignition-gazebo-diff-drive-system.so"
        name="ignition::gazebo::systems::DiffDrive">
        <left_joint>left_wheel_joint</left_joint>
        <right_joint>right_wheel_joint</right_joint>
        <wheel_separation>1.25</wheel_separation>
        <wheel_radius>0.3</wheel_radius>
        <odom_publish_frequency>50</odom_publish_frequency>
      </plugin>
      
      
      <plugin filename="libignition-gazebo-pose-publisher-system.so"
        name="ignition::gazebo::systems::PosePublisher">
        <publish_link_pose>true</publish_link_pose>
        <publish_sensor_pose>true</publish_sensor_pose>
        <publish_collision_pose>true</publish_collision_pose>
        <publish_visual_pose>true</publish_visual_pose>
        <publish_nested_model_pose>true</publish_nested_model_pose>
        <use_pose_vector_msg>true</use_pose_vector_msg>
        <static_publisher>true</static_publisher>
        <static_update_frequency>50</static_update_frequency>
      </plugin>
    </model>
    
    
    <model name='vehicle_blue2'>
      <pose>5 5 0.325 0 0 0.0</pose>
      <link name='chassis'>
        <pose>0 0 0.175 0 -0 0</pose>
        <inertial>
          <mass>0.3</mass>
          <inertia>
            <ixx>0.1</ixx>
            <ixy>0</ixy>
            <ixz>0</ixz>
            <iyy>0.1</iyy>
            <iyz>0</iyz>
            <izz>0.1</izz>
          </inertia>
        </inertial>
        <visual name='visual'>
          <geometry>
            <box>
              <size>1 1 0.568726</size>
            </box>
          </geometry>
          <material>
            <ambient>0.5 0.5 1.0 1</ambient>
            <diffuse>0.5 0.5 1.0 1</diffuse>
            <specular>0.0 0.0 1.0 1</specular>
          </material>
        </visual>
        <collision name='collision'>
          <geometry>
            <box>
              <size>1 1 0.568726</size>
            </box>
          </geometry>
        </collision>
      </link>

      <link name='left_wheel'>
        <pose>0 0.625029 -0.025 -1.5707 0 0</pose>
        <inertial>
          <mass>0.2</mass>
          <inertia>
            <ixx>0.145833</ixx>
            <ixy>0</ixy>
            <ixz>0</ixz>
            <iyy>0.145833</iyy>
            <iyz>0</iyz>
            <izz>0.125</izz>
          </inertia>
        </inertial>
        <visual name='visual'>
          <geometry>
            <sphere>
              <radius>0.3</radius>
            </sphere>
          </geometry>
          <material>
            <ambient>0.2 0.2 0.2 1</ambient>
            <diffuse>0.2 0.2 0.2 1</diffuse>
            <specular>0.2 0.2 0.2 1</specular>
          </material>
        </visual>
        <collision name='collision'>
          <geometry>
            <sphere>
              <radius>0.3</radius>
            </sphere>
          </geometry>
        </collision>
      </link>

      <link name='right_wheel'>
        <pose>0 -0.625029 -0.025 -1.5707 0 0</pose>
        <inertial>
          <mass>0.2</mass>
          <inertia>
            <ixx>0.145833</ixx>
            <ixy>0</ixy>
            <ixz>0</ixz>
            <iyy>0.145833</iyy>
            <iyz>0</iyz>
            <izz>0.125</izz>
          </inertia>
        </inertial>
        <visual name='visual'>
          <geometry>
            <sphere>
              <radius>0.3</radius>
            </sphere>
          </geometry>
          <material>
            <ambient>0.2 0.2 0.2 1</ambient>
            <diffuse>0.2 0.2 0.2 1</diffuse>
            <specular>0.2 0.2 0.2 1</specular>
          </material>
        </visual>
        <collision name='collision'>
          <geometry>
            <sphere>
              <radius>0.3</radius>
            </sphere>
          </geometry>
        </collision>
      </link>

      <link name='caster'>
        <pose>-0.5 -0 -0.125 0 -0 0</pose>
        <inertial>
          <mass>0.1</mass>
          <inertia>
            <ixx>0.1</ixx>
            <ixy>0</ixy>
            <ixz>0</ixz>
            <iyy>0.1</iyy>
            <iyz>0</iyz>
            <izz>0.1</izz>
          </inertia>
        </inertial>
        <visual name='visual'>
          <geometry>
            <sphere>
              <radius>0.2</radius>
            </sphere>
          </geometry>
          <material>
            <ambient>0.2 0.2 0.2 1</ambient>
            <diffuse>0.2 0.2 0.2 1</diffuse>
            <specular>0.2 0.2 0.2 1</specular>
          </material>
        </visual>
        <collision name='collision'>
          <geometry>
            <sphere>
              <radius>0.2</radius>
            </sphere>
          </geometry>
        </collision>
      </link>
      
      
      <link name='caster2'>
        <pose>0.5 -0 -0.125 0 -0 0</pose>
        <inertial>
          <mass>0.1</mass>
          <inertia>
            <ixx>0.1</ixx>
            <ixy>0</ixy>
            <ixz>0</ixz>
            <iyy>0.1</iyy>
            <iyz>0</iyz>
            <izz>0.1</izz>
          </inertia>
        </inertial>
        <visual name='visual'>
          <geometry>
            <sphere>
              <radius>0.2</radius>
            </sphere>
          </geometry>
          <material>
            <ambient>0.2 0.2 0.2 1</ambient>
            <diffuse>0.2 0.2 0.2 1</diffuse>
            <specular>0.2 0.2 0.2 1</specular>
          </material>
        </visual>
        <collision name='collision'>
          <geometry>
            <sphere>
              <radius>0.2</radius>
            </sphere>
          </geometry>
        </collision>
      </link>

      <joint name='left_wheel_joint' type='revolute'>
        <parent>chassis</parent>
        <child>left_wheel</child>
        <axis>
          <xyz>0 0 1</xyz>
          <limit>
            <lower>-1.79769e+308</lower>
            <upper>1.79769e+308</upper>
          </limit>
        </axis>
      </joint>

      <joint name='right_wheel_joint' type='revolute'>
        <parent>chassis</parent>
        <child>right_wheel</child>
        <axis>
          <xyz>0 0 1</xyz>
          <limit>
            <lower>-1.79769e+308</lower>
            <upper>1.79769e+308</upper>
          </limit>
        </axis>
      </joint>

      <joint name='caster_wheel' type='ball'>
        <parent>chassis</parent>
        <child>caster</child>
      </joint>
      
      <joint name='caster_wheel2' type='ball'>
        <parent>chassis</parent>
        <child>caster2</child>
      </joint>

      <plugin
        filename="libignition-gazebo-diff-drive-system.so"
        name="ignition::gazebo::systems::DiffDrive">
        <left_joint>left_wheel_joint</left_joint>
        <right_joint>right_wheel_joint</right_joint>
        <wheel_separation>1.25</wheel_separation>
        <wheel_radius>0.3</wheel_radius>
        <odom_publish_frequency>50</odom_publish_frequency>
      </plugin>
      
      
      <plugin filename="libignition-gazebo-pose-publisher-system.so"
        name="ignition::gazebo::systems::PosePublisher">
        <publish_link_pose>true</publish_link_pose>
        <publish_sensor_pose>true</publish_sensor_pose>
        <publish_collision_pose>true</publish_collision_pose>
        <publish_visual_pose>true</publish_visual_pose>
        <publish_nested_model_pose>true</publish_nested_model_pose>
        <use_pose_vector_msg>true</use_pose_vector_msg>
        <static_publisher>true</static_publisher>
        <static_update_frequency>50</static_update_frequency>
      </plugin>
    </model>
  </world>
</sdf>
